Workbook

Sheet Sheet1
A1: intern_id | B1: name | C1: department | D1: start_date | E1: end_date | F1: tasks_assigned | G1: tasks_completed | H1: avg_task_time | I1: attendance_rate | J1: performance_score | K1: feedback_score | L1: stipend | M1: projects_completed | N1: late_submissions | O1: learning_hours | P1: last_evaluation | Q1: average_montly_hours | R1: intern_duration_inDays | S1: Completion_Rate | T1: Efficiency_Score
A2: INT-001 | B2: Intern_1 | C2: Data Science | D2: 45810 | E2: 45892 | F2: 28 | G2: 18 | H2: 4 | I2: 0.7498 | J2: 7 | K2: 7.3 | L2: ₹1,500.00 | M2: 2 | N2: 2 | O2: 44 | P2: 0.6535 | Q2: 157 | R2: 82 | S2: 0.6429 | T2: 8.04
A3: INT-002 | B3: Intern_2 | C3: Data Science | D3: 45838 | E3: 45914 | F3: 34 | G3: 18 | H3: 2.3 | I3: 0.6003 | J3: 5.9 | K3: 5.3 | L3: ₹1,500.00 | M3: 3 | N3: 2 | O3: 50 | P3: 0.5194 | Q3: 174 | R3: 76 | S3: 0.5294 | T3: 10
A4: INT-003 | B4: Intern_3 | C4: Dev | D4: 45816 | E4: 45906 | F4: 34 | G4: 28 | H4: 7.2 | I4: 0.9933 | J4: 6.5 | K4: 5.8 | L4: ₹1,200.00 | M4: 5 | N4: 3 | O4: 22 | P4: 0.6419 | Q4: 154 | R4: 90 | S4: 0.8235 | T4: 5.72
A5: INT-004 | B5: Intern_4 | C5: HR | D5: 45821 | E5: 45866 | F5: 13 | G5: 10 | H5: 9.3 | I5: 0.9637 | J5: 5.4 | K5: 5.3 | L5: ₹1,000.00 | M5: 1 | N5: 3 | O5: 13 | P5: 0.5249 | Q5: 172 | R5: 45 | S5: 0.7692 | T5: 4.14
A6: INT-005 | B6: Intern_5 | C6: Data Science | D6: 45813 | E6: 45901 | F6: 24 | G6: 16 | H6: 3.6 | I6: 0.8347 | J6: 7.7 | K6: 8.4 | L6: ₹1,500.00 | M6: 2 | N6: 0 | O6: 42 | P6: 0.8039 | Q6: 160 | R6: 88 | S6: 0.6667 | T6: 9.26
A7: INT-006 | B7: Intern_6 | C7: Data Science | D7: 45813 | E7: 45877 | F7: 32 | G7: 30 | H7: 6.3 | I7: 0.966 | J7: 10 | K7: 10 | L7: ₹1,500.00 | M7: 5 | N7: 1 | O7: 38 | P7: 0.9158 | Q7: 197 | R7: 64 | S7: 0.9375 | T7: 7.44
A8: INT-007 | B8: Intern_7 | C8: HR | D8: 45831 | E8: 45897 | F8: 22 | G8: 17 | H8: 5.3 | I8: 0.9396 | J8: 4.6 | K8: 5.9 | L8: ₹1,000.00 | M8: 3 | N8: 4 | O8: 14 | P8: 0.489 | Q8: 134 | R8: 66 | S8: 0.7727 | T8: 7.29
A9: INT-008 | B9: Intern_8 | C9: Data Science | D9: 45836 | E9: 45920 | F9: 15 | G9: 10 | H9: 4.7 | I9: 0.9022 | J9: 7.5 | K9: 7.3 | L9: ₹1,500.00 | M9: 1 | N9: 3 | O9: 33 | P9: 0.7875 | Q9: 181 | R9: 84 | S9: 0.6667 | T9: 7.09
A10: INT-009 | B10: Intern_9 | C10: Data Science | D10: 45832 | E10: 45905 | F10: 12 | G10: 7 | H10: 4.8 | I10: 0.644 | J10: 7.3 | K10: 7 | L10: ₹1,500.00 | M10: 2 | N10: 0 | O10: 49 | P10: 0.7155 | Q10: 178 | R10: 73 | S10: 0.5833 | T10: 6.08
A11: INT-010 | B11: Intern_10 | C11: Data Science | D11: 45831 | E11: 45914 | F11: 21 | G11: 13 | H11: 3.7 | I11: 0.7293 | J11: 6.3 | K11: 6.3 | L11: ₹1,500.00 | M11: 1 | N11: 1 | O11: 38 | P11: 0.7532 | Q11: 120 | R11: 83 | S11: 0.619 | T11: 8.37
A12: INT-011 | B12: Intern_11 | C12: Dev | D12: 45814 | E12: 45877 | F12: 13 | G12: 7 | H12: 3.2 | I12: 0.6958 | J12: 3.9 | K12: 3.8 | L12: ₹1,200.00 | M12: 1 | N12: 2 | O12: 21 | P12: 0.4601 | Q12: 130 | R12: 63 | S12: 0.5385 | T12: 8.41
A13: INT-012 | B13: Intern_12 | C13: HR | D13: 45828 | E13: 45864 | F13: 29 | G13: 21 | H13: 7.4 | I13: 0.9266 | J13: 5 | K13: 4.6 | L13: ₹1,000.00 | M13: 2 | N13: 3 | O13: 25 | P13: 0.5548 | Q13: 152 | R13: 36 | S13: 0.7241 | T13: 4.89
... A301: INT-300 | B301: Intern_300 | C301: Data Science | D301: 45814 | E301: 45901 | F301: 38 | G301: 27 | H301: 9.9 | I301: 0.7997 | J301: 7.9 | K301: 7.3 | L301: ₹1,500.00 | M301: 4 | N301: 1 | O301: 32 | P301: 0.9009 | Q301: 126 | R301: 87 | S301: 0.7105 | T301: 3.59

Sheet Sheet2
A1: Department | B1: Avg Performance Score | C1: Avg Feedback Score | D1: Avg Task Completion Rate | E1: Avg Learning Hours
A2: Data Science | B2: =IFERROR(AVERAGEIF(Sheet1!$C$2:$C$301, $A2, Sheet1!$J$2:$J$301), 0) -> 7.7825243 | C2: =IFERROR(AVERAGEIF(Sheet1!$C$2:$C$301, $A2, Sheet1!$K$2:$K$301), 0) -> 7.8145631 | D2: =IFERROR(AVERAGEIF(Sheet1!$C$2:$C$301, $A2, Sheet1!$S$2:$S$301), 0) -> 0.69803398 | E2: =IFERROR(AVERAGEIF(Sheet1!$C$2:$C$301, $A2, Sheet1!$O$2:$O$301), 0) -> 39.902913
A3: Dev | B3: =IFERROR(AVERAGEIF(Sheet1!$C$2:$C$301, $A3, Sheet1!$J$2:$J$301), 0) -> 5.6867347 | C3: =IFERROR(AVERAGEIF(Sheet1!$C$2:$C$301, $A3, Sheet1!$K$2:$K$301), 0) -> 5.6 | D3: =IFERROR(AVERAGEIF(Sheet1!$C$2:$C$301, $A3, Sheet1!$S$2:$S$301), 0) -> 0.67866633 | E3: =IFERROR(AVERAGEIF(Sheet1!$C$2:$C$301, $A3, Sheet1!$O$2:$O$301), 0) -> 30.316327
A4: HR | B4: =IFERROR(AVERAGEIF(Sheet1!$C$2:$C$301, $A4, Sheet1!$J$2:$J$301), 0) -> 4.1222222 | C4: =IFERROR(AVERAGEIF(Sheet1!$C$2:$C$301, $A4, Sheet1!$K$2:$K$301), 0) -> 4.0787879 | D4: =IFERROR(AVERAGEIF(Sheet1!$C$2:$C$301, $A4, Sheet1!$S$2:$S$301), 0) -> 0.65060202 | E4: =IFERROR(AVERAGEIF(Sheet1!$C$2:$C$301, $A4, Sheet1!$O$2:$O$301), 0) -> 19.292929
A6: Name | B6: Department | C6: Performance Score | D6: Feedback Score | E6: Task Completion Rate
A7: =IFERROR(__xludf.DUMMYFUNCTION("SORTN({Sheet1!$B$2:$B$301, Sheet1!$C$2:$C$301, Sheet1!$J$2:$J$301, Sheet1!$K$2:$K$301, Sheet1!$S$2:$S$301}, 5, 0, 3, FALSE)"),"#REF!") -> #REF! | B7: Data Science | C7: 10 | D7: 8 | E7: 0.7941
A8: Intern_94 | B8: Dev | C8: 10 | D8: 9.5 | E8: 0.871
A9: Intern_105 | B9: Dev | C9: 9.9 | D9: 7.1 | E9: 0.8571
A10: Intern_264 | B10: Data Science | C10: 9.9 | D10: 6 | E10: 0.6
A11: Intern_18 | B11: Data Science | C11: 9.9 | D11: 7.1 | E11: 0.8333
A12: Intern_208 | B12: HR | C12: 9.9 | D12: 8.1 | E12: 0.8
A13: Intern_30 | B13: HR | C13: 9.8 | D13: 8.5 | E13: 0.75
A14: Intern_26 | B14: HR | C14: 9.8 | D14: 8.3 | E14: 0.8537 | L14: Department | M14: Avg Performance Score
A15: Intern_152 | B15: Dev | C15: 9.8 | D15: 7.5 | E15: 0.6552 | L15: Data Science | M15: 7.62
A16: Intern_51 | B16: HR | C16: 9.8 | D16: 7.4 | E16: 0.7609 | L16: Dev | M16: 7.57
L17: HR | M17: 7.37
A18: Name | B18: Department | C18: Performance Score | D18: Feedback Score | E18: Task Completion Rate (%)
A19: Intern_3 | B19: Dev | C19: 5 | D19: 9.6 | E19: 0.65
A20: Intern_12 | B20: HR | C20: 5.1 | D20: 7.3 | E20: 0.6897
A21: Intern_77 | B21: HR | C21: 5.1 | D21: 6.2 | E21: 0.8936
A22: Intern_79 | B22: Data Science | C22: 5.1 | D22: 9.6 | E22: 0.95
A23: Intern_159 | B23: HR | C23: 5.1 | D23: 8.3 | E23: 0.6739
A24: Intern_283 | B24: HR | C24: 5.1 | D24: 9.3 | E24: 0.6053
A25: Intern_289 | B25: Dev | C25: 5.1 | D25: 6.6 | E25: 0.8571
A26: Intern_23 | B26: HR | C26: 5.2 | D26: 8.1 | E26: 0.78
A27: Intern_78 | B27: HR | C27: 5.2 | D27: 8.8 | E27: 0.8065
A28: Intern_89 | B28: Dev | C28: 5.2 | D28: 8.7 | E28: 0.678
C31: Trends | D31: Trend Analysis (Correlations)
C32: Performance vs Attendance | D32: =CORREL(Sheet1!J2:J301, Sheet1!I2:I301) -> 0.45534257
C33: Performance vs Learning Hours | D33: =CORREL(Sheet1!J2:J301, Sheet1!O2:O301) -> 0.7236811
C34: Performance vs Late Submissions (Impact) | D34: =CORREL(Sheet1!J2:J301, Sheet1!N2:N301) -> -0.53303796
A46: Late Submissions | B46: Avg Performance Score
A47: Low Risk (0-1) | B47: =AVERAGEIFS(Sheet1!J:J, Sheet1!N:N, "<=1") -> 6.924812
A48: Moderate (2) | B48: =AVERAGEIFS(Sheet1!J:J, Sheet1!N:N, "=2") -> 5.6296875
A49: High Risk (3+) | B49: =AVERAGEIFS(Sheet1!J:J, Sheet1!N:N, ">=3") -> 4.715534
A55: At-Risk names
A56: =IFERROR(__xludf.DUMMYFUNCTION("FILTER(Sheet1!B:C, Sheet1!N:N >= 3)"),"name") -> name | B56: =IFERROR(__xludf.DUMMYFUNCTION("""COMPUTED_VALUE"""),"department") -> department | D56: Department | E56: Avg Efficiency Score | F56: Avg Task Time (Hrs) | G56: Task Completion Rate
A57: =IFERROR(__xludf.DUMMYFUNCTION("""COMPUTED_VALUE"""),"Intern_3") -> Intern_3 | B57: =IFERROR(__xludf.DUMMYFUNCTION("""COMPUTED_VALUE"""),"Dev") -> Dev | D57: Data Science | E57: =AVERAGEIF(Sheet1!$C:$C, A16, Sheet1!$T:$T) -> #DIV/0! | F57: =AVERAGEIF(Sheet1!$C:$C, A16, Sheet1!$H:$H) -> #DIV/0! | G57: =AVERAGEIF(Sheet1!$C:$C, A16, Sheet1!$S:$S) -> #DIV/0!
A58: =IFERROR(__xludf.DUMMYFUNCTION("""COMPUTED_VALUE"""),"Intern_4") -> Intern_4 | B58: =IFERROR(__xludf.DUMMYFUNCTION("""COMPUTED_VALUE"""),"HR") -> HR | D58: Dev
A59: =IFERROR(__xludf.DUMMYFUNCTION("""COMPUTED_VALUE"""),"Intern_7") -> Intern_7 | B59: =IFERROR(__xludf.DUMMYFUNCTION("""COMPUTED_VALUE"""),"HR") -> HR | D59: HR
...

Sheet Chart1 Average Performance Scor
A3: Department | B3: Avg Performance Score
A4: Data Science | B4: 7.62
A5: Dev | B5: 7.57
A6: HR | B6: 7.37
